#VRML_SIM R2023a utf8
# license: Apache License 2.0
# license url: http://www.apache.org/licenses/LICENSE-2.0
# This is a proto file for Webots for the RhobanPhiztech37
# Extracted from: RhobanPhiztech37/urdf/RhobanPhiztech37.urdf

EXTERNPROTO "RhobanPhiztech37_meshes/RhobanPhiztech37_tibia_1Mesh.proto"
EXTERNPROTO "RhobanPhiztech37_meshes/RhobanPhiztech37_left_foot_1_0_foot_protectionMesh.proto"
EXTERNPROTO "RhobanPhiztech37_meshes/RhobanPhiztech37_trunk_1Mesh.proto"
EXTERNPROTO "RhobanPhiztech37_meshes/RhobanPhiztech37_HandleMesh.proto"
EXTERNPROTO "RhobanPhiztech37_meshes/RhobanPhiztech37_Front_dempherMesh.proto"
EXTERNPROTO "RhobanPhiztech37_meshes/RhobanPhiztech37_u_shoulder_1Mesh.proto"
EXTERNPROTO "RhobanPhiztech37_meshes/RhobanPhiztech37_right_footMesh.proto"
EXTERNPROTO "RhobanPhiztech37_meshes/RhobanPhiztech37_left_radius_1_1_radius_plateMesh.proto"
EXTERNPROTO "RhobanPhiztech37_meshes/RhobanPhiztech37_mx106_block_mir_2Mesh.proto"
EXTERNPROTO "RhobanPhiztech37_meshes/RhobanPhiztech37_left_foot_1Mesh.proto"
EXTERNPROTO "RhobanPhiztech37_meshes/RhobanPhiztech37_right_knee_1Mesh.proto"
EXTERNPROTO "RhobanPhiztech37_meshes/RhobanPhiztech37_right_foot_1Mesh.proto"
EXTERNPROTO "RhobanPhiztech37_meshes/RhobanPhiztech37_right_foot_cleat_front_rightMesh.proto"
EXTERNPROTO "RhobanPhiztech37_meshes/RhobanPhiztech37_right_foot_cleat_back_leftMesh.proto"
EXTERNPROTO "RhobanPhiztech37_meshes/RhobanPhiztech37_right_foot_cleat_front_leftMesh.proto"
EXTERNPROTO "RhobanPhiztech37_meshes/RhobanPhiztech37_head_1Mesh.proto"
EXTERNPROTO "RhobanPhiztech37_meshes/RhobanPhiztech37_left_radius_1Mesh.proto"
EXTERNPROTO "RhobanPhiztech37_meshes/RhobanPhiztech37_cameraMesh.proto"
EXTERNPROTO "RhobanPhiztech37_meshes/RhobanPhiztech37_left_foot_cleat_front_leftMesh.proto"
EXTERNPROTO "RhobanPhiztech37_meshes/RhobanPhiztech37_left_knee_1Mesh.proto"
EXTERNPROTO "RhobanPhiztech37_meshes/RhobanPhiztech37_left_foot_cleat_back_rightMesh.proto"
EXTERNPROTO "RhobanPhiztech37_meshes/RhobanPhiztech37_left_foot_cleat_back_leftMesh.proto"
EXTERNPROTO "RhobanPhiztech37_meshes/RhobanPhiztech37_right_foot_cleat_back_rightMesh.proto"
EXTERNPROTO "RhobanPhiztech37_meshes/RhobanPhiztech37_mx106_block_2Mesh.proto"
EXTERNPROTO "RhobanPhiztech37_meshes/RhobanPhiztech37_left_footMesh.proto"
EXTERNPROTO "RhobanPhiztech37_meshes/RhobanPhiztech37_u_shoulder_2Mesh.proto"
EXTERNPROTO "RhobanPhiztech37_meshes/RhobanPhiztech37_right_foot_1_7_foot_protectionMesh.proto"
EXTERNPROTO "RhobanPhiztech37_meshes/RhobanPhiztech37_mx106_block_1Mesh.proto"
EXTERNPROTO "RhobanPhiztech37_meshes/RhobanPhiztech37_u_neck_1Mesh.proto"
EXTERNPROTO "RhobanPhiztech37_meshes/RhobanPhiztech37_right_radius_1Mesh.proto"
EXTERNPROTO "RhobanPhiztech37_meshes/RhobanPhiztech37_tibia_2Mesh.proto"
EXTERNPROTO "RhobanPhiztech37_meshes/RhobanPhiztech37_left_humerus_1Mesh.proto"
EXTERNPROTO "RhobanPhiztech37_meshes/RhobanPhiztech37_u_block_2Mesh.proto"
EXTERNPROTO "RhobanPhiztech37_meshes/RhobanPhiztech37_right_radius_1_0_radius_plateMesh.proto"
EXTERNPROTO "RhobanPhiztech37_meshes/RhobanPhiztech37_left_foot_cleat_front_rightMesh.proto"
EXTERNPROTO "RhobanPhiztech37_meshes/RhobanPhiztech37_mx106_block_mir_1Mesh.proto"
EXTERNPROTO "RhobanPhiztech37_meshes/RhobanPhiztech37_trunkMesh.proto"
EXTERNPROTO "RhobanPhiztech37_meshes/RhobanPhiztech37_right_humerus_1Mesh.proto"
EXTERNPROTO "RhobanPhiztech37_meshes/RhobanPhiztech37_head_baseMesh.proto"
EXTERNPROTO "RhobanPhiztech37_meshes/RhobanPhiztech37_u_block_1Mesh.proto"

PROTO RhobanPhiztech37 [
  field  SFVec3f     translation     0 0 0
  field  SFRotation  rotation        0 1 0 0
  field  SFString    name            "RhobanPhiztech37"  # Is `Robot.name`.
  field  SFString    controller      "ros"  # Is `Robot.controller`.
  field  MFString    controllerArgs  ["--clock" "--use-sim-time" "--name=starkit1"]      # Is `Robot.controllerArgs`.
  field  SFString    customData      ""                  # Is `Robot.customData`.
  field  SFBool      supervisor      FALSE               # Is `Robot.supervisor`.
  field  SFBool      synchronization TRUE                # Is `Robot.synchronization`.
  field  SFBool      selfCollision   FALSE               # Is `Robot.selfCollision`.
]
{
  Robot {
    translation IS translation
    rotation IS rotation
    controller IS controller
    controllerArgs IS controllerArgs
    customData IS customData
    supervisor IS supervisor
    synchronization IS synchronization
    selfCollision IS selfCollision
    children [
      RhobanPhiztech37_trunk_1Mesh {
      }
      HingeJoint {
        jointParameters HingeJointParameters {
          axis 0.000000 0.000000 -1.000000
          anchor 0.050658 -0.011238 0.184196
          dampingConstant 0.0
          staticFriction 0.0
        }
        device [
          RotationalMotor {
            name "head_yaw"
            maxTorque 12.0
          }
          PositionSensor {
            name "head_yaw_sensor"
          }
        ]
        endPoint Solid {
          translation 0.050658 -0.011238 0.184196
          rotation 0.000000 1.000000 0.000000 0.000000
          children [
            RhobanPhiztech37_u_neck_1Mesh {
            }
            HingeJoint {
              jointParameters HingeJointParameters {
                axis 0.999884 -0.015247 -0.000000
                anchor 0.000000 -0.000021 0.035704
                dampingConstant 0.0
                staticFriction 0.0
              }
              device [
                RotationalMotor {
                  name "head_pitch"
                  maxTorque 12.0
                }
                PositionSensor {
                  name "head_pitch_sensor"
                }
              ]
              endPoint Solid {
                translation 0.000000 -0.000021 0.035704
                rotation -0.577350 0.577350 -0.577350 2.094395
                children [
                  RhobanPhiztech37_head_1Mesh {
                  }

                  Camera {
                    fieldOfView            2.27  # [0, pi]
                    width                  1440 #1080 # [0, inf)
                    height                 1080 #1080    # [0, inf)
                    spherical              TRUE # {TRUE, FALSE}
                    near                   0.01    # [0, inf)
                    far                    0.0     # [0, inf)
                    exposure               1.0     # [near, inf)
                    antiAliasing           FALSE   # {TRUE, FALSE}
                    ambientOcclusionRadius 0       # [0, inf)
                    bloomThreshold         -1.0    # [-1, inf)
                    motionBlur             0.0     # [0, inf)
                    noise                  0.0     # [0, 1]
                    noiseMaskUrl           ""      # any string
                    lens                   Lens {
                                                  center                 0.5 0.5   # [0, 1] [0, 1]
                                                  radialCoefficients     0 0       # any vector
                                                  tangentialCoefficients 0 0       # any vector
                                                          }
                    focus                  NULL    # {Focus, PROTO}
                    zoom                   NULL    # {Zoom, PROTO}
                    recognition            NULL    # {Recognition, PROTO}
                    lensFlare              NULL    # {LensFlare, PROTO}
                    # translation            0.024933 -0.069050 -0.023500
                    translation 0.034212 -0.068425 0.000000
                    rotation               0.707 0.0 -0.707 3.14
                    name                   "left_camera"

                    children [
                      Solid {
                        translation 0.034212 -0.068425 0.000000
                        rotation 0.577351 0.577351 0.577350 2.094396
                        children [
                          RhobanPhiztech37_cameraMesh {
                          }
                        ]
                      }
                    ]

                    boundingObject Transform {
                      translation 0.000000 0.000000 -0.010300
                      rotation 0.000000 1.000000 0.000000 0.000000
                      children [
                        Box {
                          size 0.000500 0.000500 0.000500
                        }
                      ]
                    }

                    physics Physics {
                      density -1
                      mass 0.000001
                      centerOfMass [ 0.000000 0.000000 -0.010300 ]
                      inertiaMatrix [
                        4.062500e-14 4.062500e-14 4.062500e-14
                        -4.117500e-30 1.804900e-27 -3.702700e-30
                      ]
                    }
                  }
                ]
                name "head_1"
                boundingObject Transform {
                  translation 0.001141 -0.050940 -0.000000
                  rotation 0.000000 1.000000 0.000000 0.000000
                  children [
                    Box {
                      size 0.090750 0.130881 0.070000
                    }
                  ]
                }
                physics Physics {
                  density -1
                  mass 0.411960
                  centerOfMass [ 0.001303 -0.054289 -0.000379 ]
                  inertiaMatrix [
                    1.312500e-04 1.437000e-04 2.192700e-04
                    -7.649100e-06 1.145900e-07 -1.524700e-06
                  ]
                }
              }
            }
          ]
          name "u_neck_1"
          boundingObject Transform {
            translation 0.000000 0.000000 0.022879
            rotation 0.000000 1.000000 0.000000 0.000000
            children [
              Box {
                size 0.053000 0.047000 0.045750
              }
            ]
          }
          physics Physics {
            density -1
            mass 0.031050
            centerOfMass [ -0.000000 -0.000000 0.010359 ]
            inertiaMatrix [
              4.204800e-06 5.854900e-06 7.607700e-06
              2.563900e-12 -7.299600e-14 -1.128900e-12
            ]
          }
        }
      }
      HingeJoint {
        jointParameters HingeJointParameters {
          axis -0.000000 -0.000000 -1.000000
          anchor 0.097033 0.014615 -0.008900
          dampingConstant 0.0
          staticFriction 0.0
        }
        device [
          RotationalMotor {
            name "left_hip_yaw"
            maxTorque 12.0
          }
          PositionSensor {
            name "left_hip_yaw_sensor"
          }
        ]
        endPoint Solid {
          translation 0.097033 0.014615 -0.008900
          rotation 0.706488 -0.707725 -0.000000 3.141593
          children [
            RhobanPhiztech37_u_block_2Mesh {
            }
            HingeJoint {
              jointParameters HingeJointParameters {
                axis 0.999998 -0.001796 0.000004
                anchor 0.000000 0.000000 0.040000
                dampingConstant 0.0
                staticFriction 0.0
              }
              device [
                RotationalMotor {
                  name "left_hip_roll"
                  maxTorque 12.0
                }
                PositionSensor {
                  name "left_hip_roll_sensor"
                }
              ]
              endPoint Solid {
                translation 0.000000 0.000000 0.040000
                rotation -0.578042 -0.577005 0.577003 2.093360
                children [
                  RhobanPhiztech37_mx106_block_2Mesh {
                  }
                  HingeJoint {
                    jointParameters HingeJointParameters {
                      axis -1.000000 0.000000 0.000004
                      anchor 0.000000 0.000000 0.000000
                      dampingConstant 0.0
                      staticFriction 0.0
                    }
                    device [
                      RotationalMotor {
                        name "left_hip_pitch"
                        maxTorque 12.0
                      }
                      PositionSensor {
                        name "left_hip_pitch_sensor"
                      }
                    ]
                    endPoint Solid {
                      translation 0.000000 0.000000 0.000000
                      rotation 0.000000 1.000000 0.000000 1.570800
                      children [
                        RhobanPhiztech37_left_knee_1Mesh {
                        }
                        HingeJoint {
                          jointParameters HingeJointParameters {
                            axis 0.000000 0.000007 -1.000000
                            anchor -0.000022 -0.141000 -0.029000
                            dampingConstant 0.0
                            staticFriction 0.0
                          }
                          device [
                            RotationalMotor {
                              name "left_knee"
                              maxTorque 12.0
                            }
                            PositionSensor {
                              name "left_knee_sensor"
                            }
                          ]
                          endPoint Solid {
                            translation -0.000022 -0.141000 -0.029000
                            rotation 1.000000 0.000000 -0.000000 3.141600
                            children [
                              RhobanPhiztech37_tibia_2Mesh {
                              }
                              HingeJoint {
                                jointParameters HingeJointParameters {
                                  axis 0.000000 0.000000 1.000000
                                  anchor -0.001225 0.139995 0.000000
                                  dampingConstant 0.0
                                  staticFriction 0.0
                                }
                                device [
                                  RotationalMotor {
                                    name "left_ankle_pitch"
                                    maxTorque 12.0
                                  }
                                  PositionSensor {
                                    name "left_ankle_pitch_sensor"
                                  }
                                ]
                                endPoint Solid {
                                  translation -0.001225 0.139995 0.000000
                                  rotation 0.000000 0.000000 1.000000 3.141593
                                  children [
                                    RhobanPhiztech37_mx106_block_mir_2Mesh {
                                    }
                                    HingeJoint {
                                      jointParameters HingeJointParameters {
                                        axis 1.000000 0.000000 -0.000000
                                        anchor -0.016646 0.000000 -0.029000
                                        dampingConstant 0.0
                                        staticFriction 0.0
                                      }
                                      device [
                                        RotationalMotor {
                                          name "left_ankle_roll"
                                          maxTorque 12.0
                                        }
                                        PositionSensor {
                                          name "left_ankle_roll_sensor"
                                        }
                                      ]
                                      endPoint Solid {
                                        translation -0.016646 0.000000 -0.029000
                                        rotation 0.000000 -1.000000 0.000000 1.570796
                                        children [
                                          RhobanPhiztech37_left_foot_1Mesh {
                                          }

                                          TouchSensor {
                                            type        "force"                  # {"bumper", "force", "force-3d"}
                                            translation 0.043500 -0.052000 -0.072181
                                            rotation 1.0 0 0 1.570796
                                            lookupTable [ 0 0 0, 200 800000 0 ]   # lookup table
                                            resolution  -1                        # {-1, [0, inf)}
                                            name        "/left_pressure/pressure_2"
                                            children [
                                              Solid {
                                                translation 0.0 0.0 0.008
                                                rotation -0.9982929 -0.0486362 0.032339 1.4063477
                                                children [
                                                  RhobanPhiztech37_left_foot_cleat_back_leftMesh {
                                                  }
                                                ]
                                                name "left_foot_cleat_back_left"
                                              }
                                            ]
                                            boundingObject Transform {
                                              rotation 1.0 0 0 -1.570796
                                              children [
                                                Cylinder {
                                                      radius 0.008
                                                      height 0.018
                                                    }
                                              ]
                                            }
                                            physics Physics {
                                              density -1
                                              mass 0.002324
                                              centerOfMass [ -0.000185 0.008822 -0.001479 ]
                                              inertiaMatrix [
                                                8.110300e-08 7.082200e-08 8.081800e-08
                                                2.155800e-10 -3.614000e-11 1.724300e-09
                                              ]
                                            }
                                          }


                                          TouchSensor {
                                            type        "force"                  # {"bumper", "force", "force-3d"}
                                            translation -0.032500 -0.052000 -0.072181
                                            rotation 1.0 0 0 1.570796
                                            lookupTable [ 0 0 0, 200 800000 0 ]   # lookup table
                                            resolution  -1                        # {-1, [0, inf)}
                                            name        "/left_pressure/pressure_1"
                                            children [
                                              Solid {
                                                translation 0.0 0.0 0.008
                                                rotation -0.9982929 -0.0486362 0.032339 1.4063477
                                                children [
                                                  RhobanPhiztech37_left_foot_cleat_back_rightMesh {
                                                  }
                                                ]
                                                name "left_foot_cleat_back_right"
                                              }
                                            ]
                                          
                                            boundingObject Transform {
                                              rotation 1.0 0 0 -1.570796
                                              children [
                                                Cylinder {
                                                      radius 0.008
                                                      height 0.018
                                                    }
                                              ]
                                            }
                                            physics Physics {
                                              density -1
                                              mass 0.002324
                                              centerOfMass [ -0.000185 0.008822 -0.001479 ]
                                              inertiaMatrix [
                                                8.110300e-08 7.082171e-08 8.081845e-08
                                                2.155816e-10 -3.614039e-11 1.724327e-09
                                              ]
                                            }
                                          }


                                          TouchSensor {
                                            type        "force"                  # {"bumper", "force", "force-3d"}
                                            translation 0.043500 -0.052000 0.069428
                                            rotation 1.0 0 0 1.570796
                                            lookupTable [ 0 0 0, 200 800000 0 ]   # lookup table
                                            resolution  -1                        # {-1, [0, inf)}
                                            name        "/left_pressure/pressure_3"
                                            children [
                                              Solid {
                                                translation 0.0 0.0 0.008
                                                rotation -0.0568212 -0.7628906 0.6440258 3.0205371
                                                children [
                                                  RhobanPhiztech37_left_foot_cleat_front_leftMesh {
                                                  }
                                                ]
                                                name "left_foot_cleat_front_left"
                                              }
                                            ]
                                            boundingObject Transform {
                                              rotation 1.0 0 0 -1.570796
                                              children [
                                                Cylinder {
                                                      radius 0.008
                                                      height 0.018
                                                    }
                                              ]
                                            }
                                            physics Physics {
                                              density -1
                                              mass 0.002324
                                              centerOfMass [ -0.000172 0.008822 0.001480 ]
                                              inertiaMatrix [
                                                8.110359e-08 7.082171e-08 8.081786e-08
                                                2.010784e-10 3.374329e-11 -1.726078e-09
                                              ]
                                            }
                                          }


                                          TouchSensor {
                                            type        "force"                  # {"bumper", "force", "force-3d"}
                                            translation -0.032500 -0.052000 0.069428
                                            rotation 1.0 0 0 1.570796
                                            lookupTable [ 0 0 0, 200 800000 0 ]   # lookup table
                                            resolution  -1                        # {-1, [0, inf)}
                                            name        "/left_pressure/pressure_0"
                                            children [
                                              Solid {
                                                translation 0.0 0.0 0.008
                                                rotation -0.0568212 -0.7628906 0.6440258 3.0205371
                                                children [
                                                  RhobanPhiztech37_left_foot_cleat_front_rightMesh {
                                                  }
                                                ]
                                                name "left_foot_cleat_front_right"
                                              }
                                            ]
                                            boundingObject Transform {
                                              rotation 1.0 0 0 -1.570796
                                              children [
                                                Cylinder {
                                                      radius 0.008
                                                      height 0.018
                                                    }
                                              ]
                                            }
                                            physics Physics {
                                              density -1
                                              mass 0.002324
                                              centerOfMass [ -0.000172 0.008822 0.001480 ]
                                              inertiaMatrix [
                                                8.110359e-08 7.082171e-08 8.081786e-08
                                                2.010784e-10 3.374329e-11 -1.726078e-09
                                              ]
                                            }
                                          }

                                          Solid {
                                            translation 0.005500 -0.060250 -0.001376
                                            rotation -0.522871 -0.589049 -0.616139 2.147401
                                            children [
                                              RhobanPhiztech37_left_footMesh {
                                              }
                                            ]
                                            name "left_foot"
                                            boundingObject Transform {
                                              translation 0.000000 0.000000 0.000000
                                              rotation 0.000000 1.000000 0.000000 0.000000
                                              children [
                                                Box {
                                                  size 0.000577 0.000562 0.000522
                                                }
                                              ]
                                            }
                                            physics Physics {
                                              density -1
                                              mass 0.000001
                                              centerOfMass [ -0.000000 0.000000 0.000000 ]
                                              inertiaMatrix [
                                                4.062500e-14 4.062500e-14 4.062500e-14
                                                -4.764119e-28 6.107756e-28 9.479643e-28
                                              ]
                                            }
                                          }
                                          Solid {
                                            translation -0.012110 -0.035285 0.081064
                                            rotation -0.999981 0.003817 -0.004932 1.524854
                                            children [
                                              RhobanPhiztech37_left_foot_1_0_foot_protectionMesh {
                                              }
                                            ]
                                            name "left_foot_1_0_foot_protection"
                                            boundingObject Transform {
                                              translation 0.017545 0.024710 0.005699
                                              rotation 0.000000 1.000000 0.000000 0.000000
                                              children [
                                                Box {
                                                  size 0.090150 0.065345 0.022497
                                                }
                                              ]
                                            }
                                            physics Physics {
                                              density -1
                                              mass 0.456498
                                              centerOfMass [ 0.015507 0.020584 0.009379 ]
                                              inertiaMatrix [
                                                2.598830e-04 1.842840e-04 2.978141e-04
                                                2.772432e-07 -2.959854e-07 -2.112701e-05
                                              ]
                                            }
                                          }
                                        ]
                                        name "left_foot_1"
                                        boundingObject Transform {
                                          translation 0.005500 -0.016500 -0.001376
                                          rotation 0.000000 1.000000 0.000000 0.000000
                                          children [
                                            Box {
                                              size 0.092000 0.053000 0.157609
                                            }
                                          ]
                                        }
                                        physics Physics {
                                          density -1
                                          mass 0.210320
                                          centerOfMass [ 0.004213 -0.034512 -0.007757 ]
                                          inertiaMatrix [
                                            3.331900e-04 4.133800e-04 9.275800e-05
                                            2.971700e-07 -7.856700e-06 3.440500e-07
                                          ]
                                        }
                                      }
                                    }
                                  ]
                                  name "mx106_block_mir_2"
                                  boundingObject Transform {
                                    translation 0.021600 0.018050 -0.025850
                                    rotation 0.000000 1.000000 0.000000 0.000000
                                    children [
                                      Box {
                                        size 0.104600 0.065100 0.055300
                                      }
                                    ]
                                  }
                                  physics Physics {
                                    density -1
                                    mass 0.370800
                                    centerOfMass [ 0.020813 0.015309 -0.028797 ]
                                    inertiaMatrix [
                                      1.490300e-04 9.316700e-05 1.440100e-04
                                      -2.043600e-06 -1.290200e-10 2.021700e-06
                                    ]
                                  }
                                }
                              }
                            ]
                            name "tibia_2"
                            boundingObject Transform {
                              translation 0.003705 0.069997 -0.028000
                              rotation 0.000000 1.000000 0.000000 0.000000
                              children [
                                Box {
                                  size 0.055059 0.172163 0.060000
                                }
                              ]
                            }
                            physics Physics {
                              density -1
                              mass 0.072394
                              centerOfMass [ 0.003905 0.068115 -0.026082 ]
                              inertiaMatrix [
                                1.297000e-04 1.438200e-05 1.371900e-04
                                3.015100e-06 1.194400e-10 -1.001800e-09
                              ]
                            }
                          }
                        }
                      ]
                      name "left_knee_1"
                      boundingObject Transform {
                        translation -0.000022 -0.070811 -0.001000
                        rotation 0.000000 1.000000 0.000000 0.000000
                        children [
                          Box {
                            size 0.058000 0.169378 0.060000
                          }
                        ]
                      }
                      physics Physics {
                        density -1
                        mass 0.241750
                        centerOfMass [ -0.000020 -0.109520 -0.000391 ]
                        inertiaMatrix [
                          1.270000e-04 5.871900e-05 1.248000e-04
                          3.133000e-09 -4.400300e-09 -2.024700e-06
                        ]
                      }
                    }
                  }
                ]
                name "mx106_block_2"
                boundingObject Transform {
                  translation -0.002400 -0.018050 0.020622
                  rotation 0.000000 1.000000 0.000000 0.000000
                  children [
                    Box {
                      size 0.056800 0.065100 0.106600
                    }
                  ]
                }
                physics Physics {
                  density -1
                  mass 0.381050
                  centerOfMass [ 0.000409 -0.014897 0.020217 ]
                  inertiaMatrix [
                    1.450900e-04 9.372000e-05 1.495700e-04
                    2.027700e-06 -1.360200e-10 2.037300e-06
                  ]
                }
              }
            }
          ]
          name "u_block_2"
          boundingObject Transform {
            translation 0.004722 0.000000 0.025275
            rotation 0.000000 1.000000 0.000000 0.000000
            children [
              Box {
                size 0.056444 0.047000 0.050550
              }
            ]
          }
          physics Physics {
            density -1
            mass 0.080543
            centerOfMass [ 0.003675 -0.000006 0.008227 ]
            inertiaMatrix [
              1.264000e-05 1.704200e-05 2.626400e-05
              7.697800e-09 -3.168800e-07 5.551100e-10
            ]
          }
        }
      }
      HingeJoint {
        jointParameters HingeJointParameters {
          axis 0.000000 0.000000 1.000000
          anchor 0.004283 0.014615 -0.008900
          dampingConstant 0.0
          staticFriction 0.0
        }
        device [
          RotationalMotor {
            name "right_hip_yaw"
            maxTorque 12.0
          }
          PositionSensor {
            name "right_hip_yaw_sensor"
          }
        ]
        endPoint Solid {
          translation 0.004283 0.014615 -0.008900
          rotation 0.707107 -0.707107 -0.000000 3.141593
          children [
            RhobanPhiztech37_u_block_1Mesh {
            }
            HingeJoint {
              jointParameters HingeJointParameters {
                axis 1.000000 0.000002 -0.000000
                anchor 0.000000 0.000000 0.040000
                dampingConstant 0.0
                staticFriction 0.0
              }
              device [
                RotationalMotor {
                  name "right_hip_roll"
                  maxTorque 12.0
                }
                PositionSensor {
                  name "right_hip_roll_sensor"
                }
              ]
              endPoint Solid {
                translation 0.000000 0.000000 0.040000
                rotation -0.577351 0.577350 -0.577350 2.094394
                children [
                  RhobanPhiztech37_mx106_block_mir_1Mesh {
                  }
                  HingeJoint {
                    jointParameters HingeJointParameters {
                      axis 1.000000 0.000000 -0.000004
                      anchor -0.029000 0.000000 0.000000
                      dampingConstant 0.0
                      staticFriction 0.0
                    }
                    device [
                      RotationalMotor {
                        name "right_hip_pitch"
                        maxTorque 12.0
                      }
                      PositionSensor {
                        name "right_hip_pitch_sensor"
                      }
                    ]
                    endPoint Solid {
                      translation -0.029000 0.000000 0.000000
                      rotation 0.000000 1.000000 0.000000 1.570800
                      children [
                        RhobanPhiztech37_right_knee_1Mesh {
                        }
                        HingeJoint {
                          jointParameters HingeJointParameters {
                            axis 0.000000 -0.000000 1.000000
                            anchor 0.000000 -0.141000 0.055000
                            dampingConstant 0.0
                            staticFriction 0.0
                          }
                          device [
                            RotationalMotor {
                              name "right_knee"
                              maxTorque 12.0
                            }
                            PositionSensor {
                              name "right_knee_sensor"
                            }
                          ]
                          endPoint Solid {
                            translation 0.000000 -0.141000 0.055000
                            rotation 0.000000 0.000000 -1.000000 3.132800
                            children [
                              RhobanPhiztech37_tibia_1Mesh {
                              }
                              HingeJoint {
                                jointParameters HingeJointParameters {
                                  axis 0.000000 0.000000 1.000000
                                  anchor 0.000000 0.140000 -0.053800
                                  dampingConstant 0.0
                                  staticFriction 0.0
                                }
                                device [
                                  RotationalMotor {
                                    name "right_ankle_pitch"
                                    maxTorque 12.0
                                  }
                                  PositionSensor {
                                    name "right_ankle_pitch_sensor"
                                  }
                                ]
                                endPoint Solid {
                                  translation 0.000000 0.140000 -0.053800
                                  rotation 0.000000 0.000000 1.000000 3.132800
                                  children [
                                    RhobanPhiztech37_mx106_block_1Mesh {
                                    }
                                    HingeJoint {
                                      jointParameters HingeJointParameters {
                                        axis 1.000000 0.000000 0.000002
                                        anchor -0.007520 0.000000 0.027800
                                        dampingConstant 0.0
                                        staticFriction 0.0
                                      }
                                      device [
                                        RotationalMotor {
                                          name "right_ankle_roll"
                                          maxTorque 12.0
                                        }
                                        PositionSensor {
                                          name "right_ankle_roll_sensor"
                                        }
                                      ]
                                      endPoint Solid {
                                        translation -0.007520 0.000000 0.027800
                                        rotation -0.000000 -1.000000 0.000000 1.570798
                                        children [
                                          RhobanPhiztech37_right_foot_1Mesh {
                                          }
                                          TouchSensor {
                                            type        "force"                  # {"bumper", "force", "force-3d"}
                                            translation 0.032500 -0.052000 0.078555
                                            rotation 1.0 0 0 1.570796
                                            lookupTable [ 0 0 0, 200 800000 0 ]   # lookup table
                                            resolution  -1                        # {-1, [0, inf)}
                                            name        "/right_pressure/pressure_3"
                                            children [
                                              Solid {
                                                translation 0.0 0.0 0.008
                                                rotation 0.0636451 0.7612264 -0.6453555 3.3404908
                                                children [
                                                  RhobanPhiztech37_right_foot_cleat_front_leftMesh {
                                                  }
                                                ]
                                                name "right_foot_cleat_front_left"
                                              }
                                            ]

                                            boundingObject Transform {
                                              rotation 1.0 0 0 -1.570796
                                              children [
                                                Cylinder {
                                                      radius 0.008
                                                      height 0.018
                                                    }
                                              ]
                                            }
                                            physics Physics {
                                              density -1
                                              mass 0.002324
                                              centerOfMass [ -0.000618 0.008817 0.001392 ]
                                              inertiaMatrix [
                                                8.105712e-08 7.083473e-08 8.085131e-08
                                                7.195522e-10 1.136353e-10 -1.622330e-09
                                              ]
                                            }
                                          }


                                          TouchSensor {
                                            type        "force"                  # {"bumper", "force", "force-3d"}
                                            translation 0.032500 -0.052000 -0.063054
                                            rotation 1.0 0 0 1.570796
                                            lookupTable [ 0 0 0, 200 800000 0 ]   # lookup table
                                            resolution  -1                        # {-1, [0, inf)}
                                            name        "/right_pressure/pressure_2"
                                            children [
                                              Solid {
                                                translation 0.0 0.0 0.008
                                                rotation -0.9996955 0.0126041 0.0212164 1.4027546
                                                children [
                                                  RhobanPhiztech37_right_foot_cleat_back_leftMesh {
                                                  }
                                                ]
                                                name "right_foot_cleat_back_left"
                                              }
                                            ]
                                            boundingObject Transform {
                                              rotation 1.0 0 0 -1.570796
                                              children [
                                                Cylinder {
                                                      radius 0.008
                                                      height 0.018
                                                    }
                                              ]
                                            }
                                            physics Physics {
                                              density -1
                                              mass 0.002324
                                              centerOfMass [ 0.000270 0.008817 -0.001499 ]
                                              inertiaMatrix [
                                                8.109787e-08 7.083473e-08 8.081055e-08
                                                -3.147409e-10 5.351320e-11 1.746610e-09
                                              ]
                                            }
                                          }


                                          TouchSensor {
                                            type        "force"                  # {"bumper", "force", "force-3d"}
                                            translation -0.043500 -0.052000 -0.063054
                                            rotation 1.0 0 0 1.570796
                                            lookupTable [ 0 0 0, 200 800000 0 ]   # lookup table
                                            resolution  -1                        # {-1, [0, inf)}
                                            name        "/right_pressure/pressure_1"
                                            children [
                                              Solid {
                                                translation 0.0 0.0 0.008
                                                rotation -0.9996955 0.0126041 0.0212164 1.4027546
                                                children [
                                                  RhobanPhiztech37_right_foot_cleat_back_rightMesh {
                                                  }
                                                ]
                                                name "right_foot_cleat_back_right"
                                              }
                                            ]
                                            boundingObject Transform {
                                              rotation 1.0 0 0 -1.570796
                                              children [
                                                Cylinder {
                                                      radius 0.008
                                                      height 0.018
                                                    }
                                              ]
                                            }
                                            physics Physics {
                                              density -1
                                              mass 0.002324
                                              centerOfMass [ 0.000270 0.008817 -0.001499 ]
                                              inertiaMatrix [
                                                8.109787e-08 7.083473e-08 8.081055e-08
                                                -3.147409e-10 5.351320e-11 1.746610e-09
                                              ]
                                            }
                                          }


                                          TouchSensor {
                                            type        "force"                  # {"bumper", "force", "force-3d"}
                                            translation -0.043500 -0.052000 0.078555
                                            rotation 1.0 0 0 1.570796
                                            lookupTable [ 0 0 0, 200 800000 0 ]   # lookup table
                                            resolution  -1                        # {-1, [0, inf)}
                                            name        "/right_pressure/pressure_0"
                                            children [
                                              Solid {
                                                translation 0.0 0.0 0.008
                                                rotation 0.0636451 0.7612264 -0.6453555 3.3404908
                                                children [
                                                  RhobanPhiztech37_right_foot_cleat_front_rightMesh {
                                                  }
                                                ]
                                                name "right_foot_cleat_front_right"
                                              }
                                            ]
                                            boundingObject Transform {
                                              rotation 1.0 0 0 -1.570796
                                              children [
                                                Cylinder {
                                                      radius 0.008
                                                      height 0.018
                                                    }
                                              ]
                                            }
                                            physics Physics {
                                              density -1
                                              mass 0.002324
                                              centerOfMass [ -0.000618 0.008817 0.001392 ]
                                              inertiaMatrix [
                                                8.105712e-08 7.083473e-08 8.085131e-08
                                                7.195522e-10 1.136353e-10 -1.622330e-09
                                              ]
                                            }
                                          }

                                          Solid {
                                            translation -0.005500 -0.060250 0.007750
                                            rotation -0.538506 -0.593490 -0.598147 2.083877
                                            children [
                                              RhobanPhiztech37_right_footMesh {
                                              }
                                            ]
                                            name "right_foot"
                                            boundingObject Transform {
                                              translation 0.000000 0.000000 0.000000
                                              rotation 0.000000 1.000000 0.000000 0.000000
                                              children [
                                                Box {
                                                  size 0.000550 0.000546 0.000539
                                                }
                                              ]
                                            }
                                            physics Physics {
                                              density -1
                                              mass 0.000001
                                              centerOfMass [ 0.000000 0.000000 0.000000 ]
                                              inertiaMatrix [
                                                4.062500e-14 4.062500e-14 4.062500e-14
                                                -1.323807e-29 -2.096398e-28 1.525460e-28
                                              ]
                                            }
                                          }
                                          Solid {
                                            translation -0.025514 -0.036870 0.093482
                                            rotation -0.998661 0.015286 0.049429 1.526207
                                            children [
                                              RhobanPhiztech37_right_foot_1_7_foot_protectionMesh {
                                              }
                                            ]
                                            name "right_foot_1_7_foot_protection"
                                            boundingObject Transform {
                                              translation 0.020465 0.026180 0.006537
                                              rotation 0.000000 1.000000 0.000000 0.000000
                                              children [
                                                Box {
                                                  size 0.090499 0.069689 0.024161
                                                }
                                              ]
                                            }
                                            physics Physics {
                                              density -1
                                              mass 0.456498
                                              centerOfMass [ 0.019842 0.022712 0.010074 ]
                                              inertiaMatrix [
                                                2.595239e-04 1.846375e-04 2.978196e-04
                                                -5.497911e-06 -1.362050e-07 -2.103955e-05
                                              ]
                                            }
                                          }
                                        ]
                                        name "right_foot_1"
                                        boundingObject Transform {
                                          translation -0.005500 -0.016500 0.007750
                                          rotation 0.000000 1.000000 0.000000 0.000000
                                          children [
                                            Box {
                                              size 0.092000 0.053000 0.157609
                                            }
                                          ]
                                        }
                                        physics Physics {
                                          density -1
                                          mass 0.210320
                                          centerOfMass [ -0.004213 -0.034512 0.001369 ]
                                          inertiaMatrix [
                                            3.331900e-04 4.133800e-04 9.275800e-05
                                            -2.971400e-07 7.856700e-06 3.440500e-07
                                          ]
                                        }
                                      }
                                    }
                                  ]
                                  name "mx106_block_1"
                                  boundingObject Transform {
                                    translation 0.021600 0.018050 0.024650
                                    rotation 0.000000 1.000000 0.000000 0.000000
                                    children [
                                      Box {
                                        size 0.104600 0.065100 0.055300
                                      }
                                    ]
                                  }
                                  physics Physics {
                                    density -1
                                    mass 0.363170
                                    centerOfMass [ 0.021784 0.015631 0.027590 ]
                                    inertiaMatrix [
                                      1.483900e-04 9.284100e-05 1.436800e-04
                                      -2.037300e-06 -1.216600e-10 -2.027700e-06
                                    ]
                                  }
                                }
                              }
                            ]
                            name "tibia_1"
                            boundingObject Transform {
                              translation 0.004296 0.070000 -0.027000
                              rotation 0.000000 1.000000 0.000000 0.000000
                              children [
                                Box {
                                  size 0.054593 0.172009 0.060000
                                }
                              ]
                            }
                            physics Physics {
                              density -1
                              mass 0.072394
                              centerOfMass [ 0.004501 0.068078 -0.028918 ]
                              inertiaMatrix [
                                1.297500e-04 1.433900e-05 1.371900e-04
                                2.005600e-06 -9.900400e-11 9.979700e-10
                              ]
                            }
                          }
                        }
                      ]
                      name "right_knee_1"
                      boundingObject Transform {
                        translation 0.000000 -0.070811 0.028000
                        rotation 0.000000 1.000000 0.000000 0.000000
                        children [
                          Box {
                            size 0.058000 0.169378 0.060000
                          }
                        ]
                      }
                      physics Physics {
                        density -1
                        mass 0.241750
                        centerOfMass [ 0.000002 -0.109520 0.028609 ]
                        inertiaMatrix [
                          1.270000e-04 5.871900e-05 1.248000e-04
                          3.129900e-09 -4.403700e-09 -2.024700e-06
                        ]
                      }
                    }
                  }
                ]
                name "mx106_block_mir_1"
                boundingObject Transform {
                  translation -0.002400 -0.018050 -0.020600
                  rotation 0.000000 1.000000 0.000000 0.000000
                  children [
                    Box {
                      size 0.056800 0.065100 0.106600
                    }
                  ]
                }
                physics Physics {
                  density -1
                  mass 0.381050
                  centerOfMass [ 0.000412 -0.014897 -0.020192 ]
                  inertiaMatrix [
                    1.450900e-04 9.372000e-05 1.495700e-04
                    2.021700e-06 -1.290200e-10 -2.043600e-06
                  ]
                }
              }
            }
          ]
          name "u_block_1"
          boundingObject Transform {
            translation 0.004709 0.000000 0.025275
            rotation 0.000000 1.000000 0.000000 0.000000
            children [
              Box {
                size 0.056418 0.047000 0.050550
              }
            ]
          }
          physics Physics {
            density -1
            mass 0.081543
            centerOfMass [ 0.003374 0.000000 0.008535 ]
            inertiaMatrix [
              1.284100e-05 1.717400e-05 2.633500e-05
              -3.648200e-12 -3.268500e-07 -2.890200e-14
            ]
          }
        }
      }
      HingeJoint {
        jointParameters HingeJointParameters {
          axis 1.000000 -0.000000 -0.000000
          anchor 0.123658 -0.006258 0.155000
          dampingConstant 0.0
          staticFriction 0.0
        }
        device [
          RotationalMotor {
            name "left_shoulder_pitch"
            maxTorque 12.0
          }
          PositionSensor {
            name "left_shoulder_pitch_sensor"
          }
        ]
        endPoint Solid {
          translation 0.123658 -0.006258 0.155000
          rotation -0.577350 0.577350 -0.577350 2.094395
          children [
            RhobanPhiztech37_u_shoulder_1Mesh {
            }
            HingeJoint {
              jointParameters HingeJointParameters {
                axis 1.000000 0.000007 0.000004
                anchor 0.010350 0.030000 0.035500
                dampingConstant 0.0
                staticFriction 0.0
              }
              device [
                RotationalMotor {
                  name "left_shoulder_roll"
                  maxTorque 12.0
                }
                PositionSensor {
                  name "left_shoulder_roll_sensor"
                }
              ]
              endPoint Solid {
                translation 0.010350 0.030000 0.035500
                rotation -0.707108 -0.000003 0.707105 3.141598
                children [
                  RhobanPhiztech37_left_humerus_1Mesh {
                  }
                  HingeJoint {
                    jointParameters HingeJointParameters {
                      axis -1.000000 -0.000007 -0.000004
                      anchor -0.034722 -0.114500 0.009950
                      dampingConstant 0.0
                      staticFriction 0.0
                    }
                    device [
                      RotationalMotor {
                        name "left_elbow"
                        maxTorque 12.0
                      }
                      PositionSensor {
                        name "left_elbow_sensor"
                      }
                    ]
                    endPoint Solid {
                      translation -0.034722 -0.114500 0.009950
                      rotation 0.707105 0.000003 0.707108 3.141598
                      children [
                        RhobanPhiztech37_left_radius_1Mesh {
                        }
                        Solid {
                          translation 0.026000 0.158900 0.048722
                          rotation 0.000000 0.000000 1.000000 3.141593
                          children [
                            RhobanPhiztech37_left_radius_1_1_radius_plateMesh {
                            }
                          ]
                          name "left_radius_1_1_radius_plate"
                          boundingObject Transform {
                            translation 0.000000 0.068950 -0.014000
                            rotation 0.000000 1.000000 0.000000 0.000000
                            children [
                              Box {
                                size 0.069952 0.207900 0.028000
                              }
                            ]
                          }
                          physics Physics {
                            density -1
                            mass 0.121900
                            centerOfMass [ -0.001353 0.043804 -0.014000 ]
                            inertiaMatrix [
                              1.665600e-04 3.191900e-05 1.824500e-04
                              3.297100e-07 -2.486700e-11 8.221700e-13
                            ]
                          }
                        }
                      ]
                      name "left_radius_1"
                      boundingObject Transform {
                        translation 0.016500 0.000000 0.034722
                        rotation 0.000000 1.000000 0.000000 0.000000
                        children [
                          Box {
                            size 0.039000 0.033000 0.051000
                          }
                        ]
                      }
                      physics Physics {
                        density -1
                        mass 0.017484
                        centerOfMass [ 0.025631 -0.000000 0.034722 ]
                        inertiaMatrix [
                          8.754600e-06 9.215100e-06 4.204300e-06
                          6.142900e-22 -7.113900e-12 1.146000e-21
                        ]
                      }
                    }
                  }
                ]
                name "left_humerus_1"
                boundingObject Transform {
                  translation -0.001860 -0.057250 0.008490
                  rotation 0.000000 1.000000 0.000000 0.000000
                  children [
                    Box {
                      size 0.052280 0.142500 0.052280
                    }
                  ]
                }
                physics Physics {
                  density -1
                  mass 0.311470
                  centerOfMass [ 0.000123 -0.056873 0.010837 ]
                  inertiaMatrix [
                    1.142300e-04 7.384500e-05 1.126900e-04
                    -1.539000e-06 -3.300100e-11 1.572300e-06
                  ]
                }
              }
            }
          ]
          name "u_shoulder_1"
          boundingObject Transform {
            translation 0.000000 0.006250 0.024750
            rotation 0.000000 1.000000 0.000000 0.000000
            children [
              Box {
                size 0.053000 0.059500 0.049500
              }
            ]
          }
          physics Physics {
            density -1
            mass 0.068033
            centerOfMass [ 0.000000 0.001655 0.007658 ]
            inertiaMatrix [
              1.233600e-05 1.240500e-05 2.042900e-05
              -1.570300e-12 1.264500e-11 -1.028500e-06
            ]
          }
        }
      }
      HingeJoint {
        jointParameters HingeJointParameters {
          axis 1.000000 0.000004 -0.000004
          anchor -0.022341 -0.006258 0.155000
          dampingConstant 0.0
          staticFriction 0.0
        }
        device [
          RotationalMotor {
            name "right_shoulder_pitch"
            maxTorque 12.0
          }
          PositionSensor {
            name "right_shoulder_pitch_sensor"
          }
        ]
        endPoint Solid {
          translation -0.022341 -0.006258 0.155000
          rotation 0.577350 0.577352 0.577350 2.094399
          children [
            RhobanPhiztech37_u_shoulder_2Mesh {
            }
            HingeJoint {
              jointParameters HingeJointParameters {
                axis -1.000000 0.000000 0.000002
                anchor 0.009113 -0.030000 -0.035500
                dampingConstant 0.0
                staticFriction 0.0
              }
              device [
                RotationalMotor {
                  name "right_shoulder_roll"
                  maxTorque 12.0
                }
                PositionSensor {
                  name "right_shoulder_roll_sensor"
                }
              ]
              endPoint Solid {
                translation 0.009113 -0.030000 -0.035500
                rotation 0.000000 -1.000000 0.000000 1.570795
                children [
                  RhobanPhiztech37_right_humerus_1Mesh {
                  }
                  HingeJoint {
                    jointParameters HingeJointParameters {
                      axis 1.000000 -0.000000 0.000002
                      anchor -0.014021 -0.114500 0.009113
                      dampingConstant 0.0
                      staticFriction 0.0
                    }
                    device [
                      RotationalMotor {
                        name "right_elbow"
                        maxTorque 12.0
                      }
                      PositionSensor {
                        name "right_elbow_sensor"
                      }
                    ]
                    endPoint Solid {
                      translation -0.014021 -0.114500 0.009113
                      rotation -0.707107 0.000000 0.707106 3.141593
                      children [
                        RhobanPhiztech37_right_radius_1Mesh {
                        }
                        Solid {
                          translation 0.026000 0.159000 -0.028021
                          rotation 0.000000 0.000000 -1.000000 1.570796
                          children [
                            RhobanPhiztech37_right_radius_1_0_radius_plateMesh {
                            }
                          ]
                          name "right_radius_1_0_radius_plate"
                          boundingObject Transform {
                            translation 0.069000 0.000000 0.014000
                            rotation 0.000000 1.000000 0.000000 0.000000
                            children [
                              Box {
                                size 0.208000 0.069952 0.028000
                              }
                            ]
                          }
                          physics Physics {
                            density -1
                            mass 0.121900
                            centerOfMass [ 0.043815 0.001353 0.014000 ]
                            inertiaMatrix [
                              3.191900e-05 1.665600e-04 1.824500e-04
                              -3.297100e-07 8.221600e-13 2.486700e-11
                            ]
                          }
                        }
                      ]
                      name "right_radius_1"
                      boundingObject Transform {
                        translation 0.016500 0.000000 -0.014021
                        rotation 0.000000 1.000000 0.000000 0.000000
                        children [
                          Box {
                            size 0.039000 0.033000 0.051000
                          }
                        ]
                      }
                      physics Physics {
                        density -1
                        mass 0.017484
                        centerOfMass [ 0.025631 -0.000000 -0.014021 ]
                        inertiaMatrix [
                          8.754600e-06 9.215100e-06 4.204300e-06
                          -1.723800e-21 -1.680300e-19 1.074400e-21
                        ]
                      }
                    }
                  }
                ]
                name "right_humerus_1"
                boundingObject Transform {
                  translation -0.001860 -0.057250 0.010973
                  rotation 0.000000 1.000000 0.000000 0.000000
                  children [
                    Box {
                      size 0.052280 0.142500 0.052280
                    }
                  ]
                }
                physics Physics {
                  density -1
                  mass 0.311470
                  centerOfMass [ 0.000123 -0.056873 0.008404 ]
                  inertiaMatrix [
                    1.142300e-04 7.384500e-05 1.126900e-04
                    -1.538900e-06 -3.058900e-11 -1.572200e-06
                  ]
                }
              }
            }
          ]
          name "u_shoulder_2"
          boundingObject Transform {
            translation 0.000000 -0.006250 -0.024750
            rotation 0.000000 1.000000 0.000000 0.000000
            children [
              Box {
                size 0.053000 0.059500 0.049500
              }
            ]
          }
          physics Physics {
            density -1
            mass 0.068033
            centerOfMass [ 0.000000 -0.001655 -0.007658 ]
            inertiaMatrix [
              1.233600e-05 1.240500e-05 2.042900e-05
              -3.763000e-14 7.747200e-15 -1.028500e-06
            ]
          }
        }
      }
      Solid {
        translation 0.050658 -0.011238 0.184200
        rotation 0.000000 0.000000 -1.000000 1.570796
        children [
          RhobanPhiztech37_head_baseMesh {
          }
        ]
        name "head_base"
        boundingObject Transform {
          translation 0.000000 0.000000 0.003250
          rotation 0.000000 1.000000 0.000000 0.000000
          children [
            Box {
              size 0.000500 0.000500 0.000500
            }
          ]
        }
        physics Physics {
          density -1
          mass 0.000001
          centerOfMass [ -0.000000 0.000000 0.003250 ]
          inertiaMatrix [
            4.062500e-14 4.062500e-14 4.062500e-14
            1.509500e-29 1.558100e-29 6.487500e-30
          ]
        }
      }
      Solid {
        translation 0.050658 0.014615 -0.048900
        rotation 0.000000 0.000000 -1.000000 1.570800
        children [
          RhobanPhiztech37_trunkMesh {
          }
          InertialUnit {
            xAxis       TRUE   # {TRUE, FALSE}
            zAxis       TRUE   # {TRUE, FALSE}
            yAxis       TRUE   # {TRUE, FALSE}
            resolution  -1     # {-1, [0, inf)}
            noise       0      # {0, [0, 1)}
            name        "imu"
          }
        ]
        name "trunk"
        boundingObject Transform {
          translation 0.000000 0.000000 0.000000
          rotation 0.000000 1.000000 0.000000 0.000000
          children [
            Box {
              size 0.000500 0.000500 0.000500
            }
          ]
        }
        physics Physics {
          density -1
          mass 0.000001
          centerOfMass [ -0.000000 0.000000 -0.000000 ]
          inertiaMatrix [
            4.062500e-14 4.062500e-14 4.062500e-14
            -4.049800e-30 8.399500e-31 8.433000e-31
          ]
        }
      }
      Solid {
        translation 0.050658 -0.024258 0.141000
        rotation -0.000000 0.000000 1.000000 3.141600
        children [
          RhobanPhiztech37_Front_dempherMesh {
          }
        ]
        name "Front_dempher"
        boundingObject Transform {
          translation 0.000000 0.028425 0.000000
          rotation 0.000000 1.000000 0.000000 0.000000
          children [
            Box {
              size 0.133516 0.063849 0.020000
            }
          ]
        }
        physics Physics {
          density -1
          mass 0.092618
          centerOfMass [ -0.000000 0.023804 -0.000055 ]
          inertiaMatrix [
            3.721000e-05 1.281000e-04 1.596400e-04
            1.949000e-14 5.969000e-14 -1.017300e-07
          ]
        }
      }
      Solid {
        translation 0.119659 0.095622 0.215878
        rotation 0.017519 -0.999693 -0.017519 1.571103
        children [
          RhobanPhiztech37_HandleMesh {
          }
        ]
        name "Handle"
        boundingObject Transform {
          translation -0.027821 -0.015930 0.069000
          rotation 0.000000 1.000000 0.000000 0.000000
          children [
            Box {
              size 0.093842 0.070059 0.144000
            }
          ]
        }
        physics Physics {
          density -1
          mass 0.000000
          centerOfMass [ 0.000000 0.000000 0.000000 ]
        }
      }
    ]
    name IS name 
    boundingObject Transform {
      translation 0.050659 0.032438 0.087400
      rotation 0.000000 1.000000 0.000000 0.000000
      children [
        Box {
          size 0.158000 0.143052 0.202600
        }
      ]
    }
    physics Physics {
      density -1
      mass 3.950300
      centerOfMass [ 0.051451 0.034872 0.080966 ]
      inertiaMatrix [
        2.514600e-03 5.154600e-03 4.179300e-03
        2.325100e-06 -6.882000e-07 8.163500e-06
      ]
    }
  }
}
